<!-- https://juejin.cn/post/6959043611161952269 -->
Promise.resolve().then(() => {
  return new Error('error!!!')
}).then(res => {
  console.log("then: ", res)
}).catch(err => {
  console.log("catch: ", err)
})

返回任意一个非 promise 的值都会被包裹成 promise 对象，因此这里的return new Error('error!!!')也被包裹成了return Promise.resolve(new Error('error!!!'))，因此它会被then捕获而不是catch。
